<?xml version="1.0" encoding="UTF-8"?>
<!DOCTYPE xml>
<robot xmlns:xacro="http://www.ros.org/wiki/xacro" name="robot_3">

  <xacro:property name="L1" value="0.08" />
  <xacro:property name="L1radius" value="0.03" />
  <xacro:property name="L2" value="0.06" />
  <xacro:property name="L2radius" value="0.015" />
  <xacro:property name="L3" value="0.06" />
  <xacro:property name="L3radius" value="0.02" />
  <xacro:property name="eesize" value="0.05" />
  <xacro:property name="J1MIN" value="-0.08" />
  <xacro:property name="J1MAX" value="0.08" />
  <xacro:property name="J2MIN" value="${-pi/2}" />
  <xacro:property name="J2MAX" value="${pi/2}" />
  <xacro:property name="J3MIN" value="-0.04" />
  <xacro:property name="J3MAX" value="0.04" />

  <material name="blue">
    <color rgba="0.2 0.4 0.65 1" />
  </material>

  <material name="yellow">
    <color rgba="1 0.85 0 1" />
  </material>

  <link name="world" />

  <link name="base">
  <visual name="base">
      <origin xyz="0 0 0.14" />
      <geometry>
        <box size = "0.01 0.01 0.28" />
      </geometry>
      <material name="blue" />
    </visual>
  </link>

  <link name="link1">
    <visual name="link1">
      <origin xyz="${L1/2} 0 0" />
      <geometry>
        <box size = "${L1} 0.03 0.03" />
      </geometry>
      <material name="blue" />
    </visual>
  </link>

  <link name="link2">
    <visual name="link2">
      <origin xyz="0 ${L2/2} 0" rpy="${pi/2} ${pi/2} 0"/>
      <geometry>
        <cylinder radius="${L2radius}" length="${L2}" />
      </geometry>
      <material name="blue" />
    </visual>
  </link>

  <link name="link3">
    <visual name="link3">
      <origin xyz="0 0 ${L3/2}" />
      <geometry>
        <cylinder radius="${L3radius}" length="${L3}" />
      </geometry>
      <material name="blue" />
    </visual>
  </link>

  <link name="ee">
    <visual name="ee">
      <origin xyz="0 0 0" />
      <geometry>
        <box size="${eesize} ${eesize} ${eesize}" />
      </geometry>
      <material name="yellow" />
    </visual>
  </link>

  <joint name="base_in_world" type="fixed">
    <parent link="world" />
    <child link="base" />
    <origin xyz="${-(L1+L2+L3)} 0 0" rpy="0 0 0" />
  </joint>

  <joint name="joint1" type="prismatic">
    <parent link="base" />
    <child link="link1" />
    <origin xyz="0 0 0.2" rpy="0 0 0" />
    <axis xyz="0 0 1" />
    <limit lower="${J1MIN}" upper="${J1MAX}" effort="1" velocity="1" />
  </joint>

  <joint name="joint2" type="revolute">
    <parent link="link1" />
    <child link="link2" />
    <origin xyz="${L1} 0 0" rpy="0 0 ${-pi/2}" />
    <axis xyz="0 0 1" />
    <limit lower="${J2MIN}" upper="${J2MAX}" effort="1" velocity="1" />
  </joint>

  <joint name="joint3" type="prismatic">
    <parent link="link2" />
    <child link="link3" />
    <origin xyz="0 ${L2} 0" rpy="${-pi/2} 0 0" />
    <axis xyz="0 0 1" />
    <limit lower="${J3MIN}" upper="${J3MAX}" effort="1" velocity="1" />
  </joint>

  <joint name="ee_in_link3" type="fixed">
    <parent link="link3" />
    <child link="ee" />
    <origin xyz="0 0 ${L3}" rpy="0 0 0" />
  </joint>

</robot>